Workbook

Sheet Client Data
A1: Client ID | B1: Name | C1: Type | D1: Phone | E1: Min Budget | F1: Max Budget | G1: Status
A2: C-01 | B2: James Wilson | C2: Buyer | D2: 555-0101 | E2: $9,720 | F2: $9,900 | G2: Active
A3: C-02 | B3: Mary Thompson | C3: Tenant | D3: 555-0102 | E3: $28,350 | F3: $28,600 | G3: New
A4: C-03 | B4: Robert Garcia | C4: Buyer | D4: 555-0103 | E4: $17,010 | F4: $17,200 | G4: Active
A5: C-04 | B5: Patricia Martinez | C5: Tenant | D5: 555-0104 | E5: $34,020 | F5: $34,300 | G5: Closed
A6: C-05 | B6: Michael Robinson | C6: Buyer | D6: 555-0105 | E6: $85,500 | F6: $86,000 | G6: New
A7: C-06 | B7: Linda Clark | C7: Tenant | D7: 555-0106 | E7: $8,123 | F7: $8,250 | G7: Closed
A8: C-07 | B8: William Rodriguez | C8: Buyer | D8: 555-0107 | E8: $42,750 | F8: $43,200 | G8: Active
A9: C-08 | B9: Elizabeth Lewis | C9: Tenant | D9: 555-0108 | E9: $7,125 | F9: $7,250 | G9: New
A10: C-09 | B10: David Walker | C10: Buyer | D10: 555-0109 | E10: $8,910 | F10: $9,050 | G10: Active
A11: C-10 | B11: Barbara Hall | C11: Tenant | D11: 555-0110 | E11: $12,150 | F11: $12,300 | G11: Inactive
A12: C-11 | B12: Christopher Allen | C12: Buyer | D12: 555-0111 | E12: $11,535 | F12: $11,700 | G12: New
... A21: C-20 | B21: Sarah Adams | C21: Tenant | D21: 555-0120 | E21: $10,688 | F21: $10,900 | G21: New

Sheet Properties
A1: Property ID | B1: Type | C1: Listing | D1: Address | E1: Area (sqft) | F1: Price | G1: Commission % | H1: Profit in Figures | I1: Status | J1: Agent | K1: Property Category
A2: P-01 | B2: Apartment | C2: Sale | D2: 12 Marina Dr | E2: 1200 | F2: =E2*9 -> 10800 | G2: 0.03 | H2: =F2*G2 -> 324 | I2: Available | J2: Sarah J. | K2: =IF(F2 > 100000, "Luxury", "Standard") -> Standard
A3: P-02 | B3: Villa | C3: Rent | D3: 45 Sunset Blvd | E3: 3500 | F3: =E3*9 -> 31500 | G3: 0.05 | H3: =F3*G3 -> 1575 | I3: Available | J3: Mike R. | K3: =IF(F3 > 100000, "Luxury", "Standard") -> Standard
A4: P-03 | B4: Commercial | C4: Sale | D4: 88 Biz Hub | E4: 2100 | F4: =E4*9 -> 18900 | G4: 0.04 | H4: =F4*G4 -> 756 | I4: Sold | J4: David L. | K4: =IF(F4 > 100000, "Luxury", "Standard") -> Standard
A5: P-04 | B5: Land | C5: Sale | D5: Plot 7, Sector 5 | E5: 10000 | F5: =E5*9 -> 90000 | G5: 0.05 | H5: =F5*G5 -> 4500 | I5: Available | J5: Emma W. | K5: =IF(F5 > 100000, "Luxury", "Standard") -> Standard
A6: P-05 | B6: Apartment | C6: Rent | D6: 78 Sky Tower | E6: 950 | F6: =E6*9 -> 8550 | G6: 0.1 | H6: =F6*G6 -> 855 | I6: Rented | J6: Sarah J. | K6: =IF(F6 > 100000, "Luxury", "Standard") -> Standard
A7: P-06 | B7: Villa | C7: Sale | D7: 22 Palm Court | E7: 4200 | F7: =E7*9 -> 37800 | G7: 0.025 | H7: =F7*G7 -> 945 | I7: Under Offer | J7: Mike R. | K7: =IF(F7 > 100000, "Luxury", "Standard") -> Standard
A8: P-07 | B8: Apartment | C8: Sale | D8: 34 City Center | E8: 1100 | F8: =E8*9 -> 9900 | G8: 0.03 | H8: =F8*G8 -> 297 | I8: Available | J8: David L. | K8: =IF(F8 > 100000, "Luxury", "Standard") -> Standard
A9: P-08 | B9: Commercial | C9: Rent | D9: Unit 4, Mall X | E9: 1500 | F9: =E9*9 -> 13500 | G9: 0.1 | H9: =F9*G9 -> 1350 | I9: Under Offer | J9: Emma W. | K9: =IF(F9 > 100000, "Luxury", "Standard") -> Standard
A10: P-09 | B10: Villa | C10: Rent | D10: 9 Rose Garden | E10: 3800 | F10: =E10*9 -> 34200 | G10: 0.05 | H10: =F10*G10 -> 1710 | I10: Rented | J10: Sarah J. | K10: =IF(F10 > 100000, "Luxury", "Standard") -> Standard
A11: P-10 | B11: Apartment | C11: Sale | D11: 56 North View | E11: 1350 | F11: =E11*9 -> 12150 | G11: 0.03 | H11: =F11*G11 -> 364.5 | I11: Available | J11: Mike R. | K11: =IF(F11 > 100000, "Luxury", "Standard") -> Standard
A12: P-11 | B12: Land | C12: Sale | D12: Hillside Plot 2 | E12: 15000 | F12: =E12*9 -> 135000 | G12: 0.05 | H12: =F12*G12 -> 6750 | I12: Rented | J12: David L. | K12: =IF(F12 > 100000, "Luxury", "Standard") -> Luxury
A13: P-12 | B13: Apartment | C13: Rent | D13: 101 Lake View | E13: 1000 | F13: =E13*9 -> 9000 | G13: 0.1 | H13: =F13*G13 -> 900 | I13: Available | J13: Emma W. | K13: =IF(F13 > 100000, "Luxury", "Standard") -> Standard
... A41: P-40 | B41: Apartment | C41: Sale | D41: 18 Sunrise Lane | E41: 1400 | F41: =E41*9 -> 12600 | G41: 0.03 | H41: =F41*G41 -> 378 | I41: Available | J41: Emma W. | K41: =IF(F41 > 100000, "Luxury", "Standard") -> Standard

Sheet Deal data
A1: Deal ID | B1: Property ID | C1: Client ID | D1: Agent | E1: Deal Value | F1: Commission % | G1: Gross Commission | H1: Payment Mode | I1: Loan Amount | J1: Duration (Years) | K1: Interest Rate | L1: EMI | M1: Deal Status
A2: D-01 | B2: P-03 | C2: C-03 | D2: David L. | E2: 17010 | F2: 0.04 | G2: =E2*F2 -> 680.4 | H2: Mortgage | I2: 11907 | J2: 20 | K2: =B323/100 -> 0.002 | L2: =(I2*(B323/12/100)*POWER(1+(B323/12/100),J2*12)) / (POWER(1+(B323/12/100),J2*12)-1) -> 50.615499 | M2: Active
A3: D-02 | B3: P-05 | C3: C-06 | D3: Sarah J. | E3: 8122.5 | F3: 0.1 | G3: =E3*F3 -> 812.25 | H3: Cash | I3: 0 | J3: 0 | K3: =B324/100 -> 0 | L3: 0 | M3: Completed
A4: D-03 | B4: P-13 | C4: C-07 | D4: Sarah J. | E4: 42750 | F4: 0.02 | G4: =E4*F4 -> 855 | H4: Mortgage | I4: 29925 | J4: 15 | K4: =B325/100 -> 0.115 | L4: =(I4*(B325/12/100)*POWER(1+(B325/12/100),J4*12)) / (POWER(1+(B325/12/100),J4*12)-1) -> 349.5808 | M4: Pending
A5: D-04 | B5: P-09 | C5: C-04 | D5: Sarah J. | E5: 34020 | F5: 0.05 | G5: =E5*F5 -> 1701 | H5: Mortgage | I5: 23814 | J5: 25 | K5: =B326/100 -> 0.13 | L5: =(I5*(B326/12/100)*POWER(1+(B326/12/100),J5*12)) / (POWER(1+(B326/12/100),J5*12)-1) -> 268.5827 | M5: Active
A6: D-05 | B6: P-16 | C6: C-08 | D6: Emma W. | E6: 7125 | F6: 0.05 | G6: =E6*F6 -> 356.25 | H6: Cash | I6: 0 | J6: 0 | K6: =B327/100 -> 0 | L6: 0 | M6: Completed
A7: D-06 | B7: P-22 | C7: C-15 | D7: Mike R. | E7: 32400 | F7: 0.03 | G7: =E7*F7 -> 972 | H7: Mortgage | I7: 22680 | J7: 20 | K7: =B328/100 -> 0.12 | L7: =(I7*(B328/12/100)*POWER(1+(B328/12/100),J7*12)) / (POWER(1+(B328/12/100),J7*12)-1) -> 249.72634 | M7: Active
A8: D-07 | B8: P-30 | C8: C-21 | D8: David L. | E8: 35100 | F8: 0.025 | G8: =E8*F8 -> 877.5 | H8: Cash | I8: 0 | J8: 0 | K8: =B329/100 -> 0 | L8: 0 | M8: Completed
A9: D-08 | B9: P-01 | C9: C-01 | D9: Sarah J. | E9: 9720 | F9: 0.03 | G9: =E9*F9 -> 291.6 | H9: Mortgage | I9: 6804 | J9: 15 | K9: =B330/100 -> 0.11 | L9: =(I9*(B330/12/100)*POWER(1+(B330/12/100),J9*12)) / (POWER(1+(B330/12/100),J9*12)-1) -> 77.334055 | M9: Pending
A10: D-09 | B10: P-02 | C10: C-02 | D10: Mike R. | E10: 28350 | F10: 0.05 | G10: =E10*F10 -> 1417.5 | H10: Mortgage | I10: 19845 | J10: 20 | K10: =B331/100 -> 0.125 | L10: =(I10*(B331/12/100)*POWER(1+(B331/12/100),J10*12)) / (POWER(1+(B331/12/100),J10*12)-1) -> 225.46709 | M10: Active
A11: D-10 | B11: P-04 | C11: C-05 | D11: Emma W. | E11: 85500 | F11: 0.05 | G11: =E11*F11 -> 4275 | H11: Cash | I11: 0 | J11: 0 | K11: =B332/100 -> 0 | L11: 0 | M11: Completed
A12: D-11 | B12: P-06 | C12: C-07 | D12: Mike R. | E12: 34020 | F12: 0.025 | G12: =E12*F12 -> 850.5 | H12: Mortgage | I12: 23814 | J12: 18 | K12: =B333/100 -> 0.1175 | L12: =(I12*(B333/12/100)*POWER(1+(B333/12/100),J12*12)) / (POWER(1+(B333/12/100),J12*12)-1) -> 265.54337 | M12: Active
A13: D-12 | B13: P-07 | C13: C-09 | D13: David L. | E13: 8910 | F13: 0.03 | G13: =E13*F13 -> 267.3 | H13: Cash | I13: 0 | J13: 0 | K13: =B334/100 -> 0 | L13: 0 | M13: Completed
A14: D-13 | B14: P-08 | C14: C-10 | D14: Emma W. | E14: 12150 | F14: 0.1 | G14: =E14*F14 -> 1215 | H14: Mortgage | I14: 8505 | J14: 20 | K14: =B335/100 -> 0.12 | L14: =(I14*(B335/12/100)*POWER(1+(B335/12/100),J14*12)) / (POWER(1+(B335/12/100),J14*12)-1) -> 93.647376 | M14: Pending
A15: D-14 | B15: P-10 | C15: C-11 | D15: Mike R. | E15: 11535 | F15: 0.03 | G15: =E15*F15 -> 346.05 | H15: Mortgage | I15: 8074.5 | J15: 25 | K15: =B336/100 -> 0.135 | L15: =(I15*(B336/12/100)*POWER(1+(B336/12/100),J15*12)) / (POWER(1+(B336/12/100),J15*12)-1) -> 94.119996 | M15: Active
A16: D-15 | B16: P-11 | C16: C-12 | D16: David L. | E16: 128250 | F16: 0.05 | G16: =E16*F16 -> 6412.5 | H16: Cash | I16: 0 | J16: 0 | K16: =B337/100 -> 0 | L16: 0 | M16: Completed
A17: D-16 | B17: P-12 | C17: C-13 | D17: Emma W. | E17: 8550 | F17: 0.1 | G17: =E17*F17 -> 855 | H17: Mortgage | I17: 5985 | J17: 15 | K17: =B338/100 -> 0.1125 | L17: =(I17*(B338/12/100)*POWER(1+(B338/12/100),J17*12)) / (POWER(1+(B338/12/100),J17*12)-1) -> 68.967825 | M17: Active
A18: D-17 | B18: P-14 | C18: C-14 | D18: Mike R. | E18: 44550 | F18: 0.02 | G18: =E18*F18 -> 891 | H18: Cash | I18: 0 | J18: 0 | K18: =B339/100 -> 0 | L18: 0 | M18: Completed
A19: D-18 | B19: P-15 | C19: C-15 | D19: David L. | E19: 7267.5 | F19: 0.03 | G19: =E19*F19 -> 218.025 | H19: Mortgage | I19: 5087.25 | J19: 20 | K19: =B340/100 -> 0.12 | L19: =(I19*(B340/12/100)*POWER(1+(B340/12/100),J19*12)) / (POWER(1+(B340/12/100),J19*12)-1) -> 56.015004 | M19: Pending
A20: D-19 | B20: P-17 | C20: C-16 | D20: Sarah J. | E20: 202500 | F20: 0.05 | G20: =E20*F20 -> 10125 | H20: Mortgage | I20: 141750 | J20: 22 | K20: =B341/100 -> 0.13 | L20: =(I20*(B341/12/100)*POWER(1+(B341/12/100),J20*12)) / (POWER(1+(B341/12/100),J20*12)-1) -> 1630.4459 | M20: Active
A21: D-20 | B21: P-18 | C21: C-17 | D21: Mike R. | E21: 8910 | F21: 0.1 | G21: =E21*F21 -> 891 | H21: Cash | I21: 0 | J21: 0 | K21: =B342/100 -> 0 | L21: 0 | M21: Completed
A22: D-21 | B22: P-19 | C22: C-18 | D22: David L. | E22: 9720 | F22: 0.1 | G22: =E22*F22 -> 972 | H22: Mortgage | I22: 6804 | J22: 18 | K22: =B343/100 -> 0.115 | L22: =(I22*(B343/12/100)*POWER(1+(B343/12/100),J22*12)) / (POWER(1+(B343/12/100),J22*12)-1) -> 74.728008 | M22: Active
A23: D-22 | B23: P-20 | C23: C-19 | D23: Emma W. | E23: 38220 | F23: 0.03 | G23: =E23*F23 -> 1146.6 | H23: Cash | I23: 0 | J23: 0 | K23: =B344/100 -> 0 | L23: 0 | M23: Completed
A24: D-23 | B24: P-21 | C24: C-20 | D24: Sarah J. | E24: 10687.5 | F24: 0.03 | G24: =E24*F24 -> 320.625 | H24: Mortgage | I24: 7481.25 | J24: 20 | K24: =B345/100 -> 0.1225 | L24: =(I24*(B345/12/100)*POWER(1+(B345/12/100),J24*12)) / (POWER(1+(B345/12/100),J24*12)-1) -> 83.68262 | M24: Pending
A25: D-24 | B25: P-23 | C25: C-22 | D25: David L. | E25: 25200 | F25: 0.04 | G25: =E25*F25 -> 1008 | H25: Mortgage | I25: 17640 | J25: 25 | K25: =B346/100 -> 0.13 | L25: =(I25*(B346/12/100)*POWER(1+(B346/12/100),J25*12)) / (POWER(1+(B346/12/100),J25*12)-1) -> 198.95015 | M25: Active
A26: D-25 | B26: P-24 | C26: C-23 | D26: Emma W. | E26: 153900 | F26: 0.05 | G26: =E26*F26 -> 7695 | H26: Cash | I26: 0 | J26: 0 | K26: =B347/100 -> 0 | L26: 0 | M26: Completed
A27: D-26 | B27: P-25 | C27: C-24 | D27: Sarah J. | E27: 7695 | F27: 0.1 | G27: =E27*F27 -> 769.5 | H27: Mortgage | I27: 5386.5 | J27: 15 | K27: =B348/100 -> 0.1175 | L27: =(I27*(B348/12/100)*POWER(1+(B348/12/100),J27*12)) / (POWER(1+(B348/12/100),J27*12)-1) -> 63.783236 | M27: Active
A28: D-27 | B28: P-26 | C28: C-25 | D28: Mike R. | E28: 40800 | F28: 0.025 | G28: =E28*F28 -> 1020 | H28: Cash | I28: 0 | J28: 0 | K28: =B349/100 -> 0 | L28: 0 | M28: Completed
A29: D-28 | B29: P-27 | C29: C-26 | D29: David L. | E29: 12150 | F29: 0.1 | G29: =E29*F29 -> 1215 | H29: Mortgage | I29: 8505 | J29: 20 | K29: =B350/100 -> 0.125 | L29: =(I29*(B350/12/100)*POWER(1+(B350/12/100),J29*12)) / (POWER(1+(B350/12/100),J29*12)-1) -> 96.628754 | M29: Pending
A30: D-29 | B30: P-28 | C30: C-27 | D30: Emma W. | E30: 8977.5 | F30: 0.03 | G30: =E30*F30 -> 269.325 | H30: Mortgage | I30: 6284.25 | J30: 25 | K30: =B351/100 -> 0.1325 | L30: =(I30*(B351/12/100)*POWER(1+(B351/12/100),J30*12)) / (POWER(1+(B351/12/100),J30*12)-1) -> 72.061522 | M30: Active
A31: D-30 | B31: P-29 | C31: C-28 | D31: Sarah J. | E31: 256500 | F31: 0.05 | G31: =E31*F31 -> 12825 | H31: Cash | I31: 0 | J31: 0 | K31: =B352/100 -> 0 | L31: 0 | M31: Completed
A32: D-31 | B32: P-31 | C32: C-29 | D32: David L. | E32: 10530 | F32: 0.03 | G32: =E32*F32 -> 315.9 | H32: Mortgage | I32: 7371 | J32: 18 | K32: =B353/100 -> 0.115 | L32: =(I32*(B353/12/100)*POWER(1+(B353/12/100),J32*12)) / (POWER(1+(B353/12/100),J32*12)-1) -> 80.955342 | M32: Active
A33: D-32 | B33: P-32 | C33: C-30 | D33: Emma W. | E33: 50220 | F33: 0.02 | G33: =E33*F33 -> 1004.4 | H33: Cash | I33: 0 | J33: 0 | K33: =B354/100 -> 0 | L33: 0 | M33: Completed
A34: D-33 | B34: P-33 | C34: C-31 | D34: Sarah J. | E34: 8838 | F34: 0.1 | G34: =E34*F34 -> 883.8 | H34: Mortgage | I34: 6186.6 | J34: 20 | K34: =B355/100 -> 0.12 | L34: =(I34*(B355/12/100)*POWER(1+(B355/12/100),J34*12)) / (POWER(1+(B355/12/100),J34*12)-1) -> 68.119795 | M34: Pending
A35: D-34 | B35: P-34 | C35: C-32 | D35: Mike R. | E35: 46800 | F35: 0.02 | G35: =E35*F35 -> 936 | H35: Mortgage | I35: 32760 | J35: 22 | K35: =B356/100 -> 0.13 | L35: =(I35*(B356/12/100)*POWER(1+(B356/12/100),J35*12)) / (POWER(1+(B356/12/100),J35*12)-1) -> 376.81416 | M35: Active
A36: D-35 | B36: P-35 | C36: C-33 | D36: David L. | E36: 198000 | F36: 0.05 | G36: =E36*F36 -> 9900 | H36: Cash | I36: 0 | J36: 0 | K36: =B357/100 -> 0 | L36: 0 | M36: Completed
A37: D-36 | B37: P-36 | C37: C-34 | D37: Emma W. | E37: 12960 | F37: 0.1 | G37: =E37*F37 -> 1296 | H37: Mortgage | I37: 9072 | J37: 15 | K37: =B358/100 -> 0.1125 | L37: =(I37*(B358/12/100)*POWER(1+(B358/12/100),J37*12)) / (POWER(1+(B358/12/100),J37*12)-1) -> 104.5407 | M37: Active
A38: D-37 | B38: P-37 | C38: C-35 | D38: Sarah J. | E38: 9315 | F38: 0.03 | G38: =E38*F38 -> 279.45 | H38: Cash | I38: 0 | J38: 0 | K38: =B359/100 -> 0 | L38: 0 | M38: Completed
A39: D-38 | B39: P-38 | C39: C-36 | D39: Mike R. | E39: 46800 | F39: 0.05 | G39: =E39*F39 -> 2340 | H39: Mortgage | I39: 32760 | J39: 20 | K39: =B360/100 -> 0.125 | L39: =(I39*(B360/12/100)*POWER(1+(B360/12/100),J39*12)) / (POWER(1+(B360/12/100),J39*12)-1) -> 372.19964 | M39: Pending
A40: D-39 | B40: P-39 | C40: C-37 | D40: David L. | E40: 48960 | F40: 0.03 | G40: =E40*F40 -> 1468.8 | H40: Mortgage | I40: 34272 | J40: 25 | K40: =B361/100 -> 0.13 | L40: =(I40*(B361/12/100)*POWER(1+(B361/12/100),J40*12)) / (POWER(1+(B361/12/100),J40*12)-1) -> 386.53172 | M40: Active
...

Sheet Summary & Calculations
A1: Metric | B1: Calculation | E1: Total (Type of client) | J1: Total (Status of Client) | O1: Total (Type of Property) | S1: Total (Status of Properties) | X1: Payment Mode (Status) | AB1: Apartment Status | AD1: Villa Status
A2: Total Sales Value | B2: =SUMIFS('Deal data'!E:E,'Deal data'!E:E,">10000") -> 1671832.5
A3: Total Rental Value | B3: =SUMIFS('Deal data'!E:E,'Deal data'!E:E,"<10000") -> 103150.5 | E3: Buyer | F3: =COUNTIF('Client Data'!C:C, "Buyer") -> 9 | J3: Active | K3: =COUNTIF('Client Data'!G:G, "Active") -> 8 | O3: Apartment | P3: =COUNTIF(Properties!B:B,"Apartment") -> 14 | S3: Avaiable | T3: =COUNTIF(Properties!I:I, "Available") -> 23 | X3: Mortgage | Y3: =COUNTIF('Deal data'!H:H, "Mortgage") -> 24 | AB3: Available | AC3: =COUNTIFS(Properties!B:B, "Apartment", Properties!I:I, "Available") -> 9 | AD3: Available | AE3: =COUNTIFS(Properties!B:B, "Villa", Properties!I:I, "Available") -> 5
A4: Total Gross Commission | B4: =SUM('Deal data'!G:G) -> 80334.375 | E4: Tenant | F4: =COUNTIF('Client Data'!C:C, "Tenant") -> 11 | J4: Inactive | K4: =COUNTIF('Client Data'!G:G, "Inactive") -> 2 | O4: Villa | P4: =COUNTIF(Properties!B:B,"Villa") -> 11 | S4: Under Offer | T4: =COUNTIF(Properties!I:I, "Under Offer") -> 4 | X4: Cash | Y4: =COUNTIF('Deal data'!H:H, "Cash") -> 16 | AB4: Sold | AC4: =COUNTIFS(Properties!B:B, "Apartment", Properties!I:I, "Sold") -> 3 | AD4: Sold | AE4: =COUNTIFS(Properties!B:B, "Villa", Properties!I:I, "Sold") -> 3
A5: Operational Expenses | B5: 50000 | J5: New | K5: =COUNTIF('Client Data'!G:G, "New") -> 6 | O5: Commercial | P5: =COUNTIF(Properties!B:B,"Commercial") -> 9 | S5: Rented | T5: =COUNTIF(Properties!I:I, "Rented") -> 5 | AB5: Rented | AC5: =COUNTIFS(Properties!B:B, "Apartment", Properties!I:I, "Rented") -> 2 | AD5: Rented | AE5: =COUNTIFS(Properties!B:B, "Villa", Properties!I:I, "Rented") -> 2
A6: Net Profit | B6: =B4-B5 -> 30334.375 | J6: Closed | K6: =COUNTIF('Client Data'!G:G, "Closed") -> 4 | O6: Land | P6: =COUNTIF(Properties!B:B,"Land") -> 6 | S6: Sold | T6: =COUNTIF(Properties!I:I, "Sold") -> 8 | AB6: Under Offer | AC6: =COUNTIFS(Properties!B:B, "Apartment", Properties!I:I, "Under Offer") -> 0 | AD6: Under Offer | AE6: =COUNTIFS(Properties!B:B, "Villa", Properties!I:I, "Under Offer") -> 1
A7: Average Deal Value | B7: =AVERAGE('Deal data'!E:E) -> 44374.575 | AB7: Commercial Status | AD7: Land Status
AB9: Available | AC9: =COUNTIFS(Properties!B:B, "Commercial", Properties!I:I, "Available") -> 4 | AD9: Available | AE9: =COUNTIFS(Properties!B:B, "Land", Properties!I:I, "Available") -> 5
AB10: Sold | AC10: =COUNTIFS(Properties!B:B, "Commercial", Properties!I:I, "Sold") -> 2 | AD10: Sold | AE10: =COUNTIFS(Properties!B:B, "Land", Properties!I:I, "Sold") -> 0
AB11: Rented | AC11: =COUNTIFS(Properties!B:B, "Commercial", Properties!I:I, "Rented") -> 0 | AD11: Rented | AE11: NIL
AB12: Under Offer | AC12: =COUNTIFS(Properties!B:B, "Commercial", Properties!I:I, "Under OFFEr") -> 3 | AD12: Under Offer | AE12: =COUNTIFS(Properties!B:B, "Land", Properties!I:I, "Under Offer") -> 0
